# Socket.IO Follow-up Message Error Fix

## Problem Identified
The Socket.IO error on follow-up messages was likely caused by a **type conversion issue** with `session_id`. 

When the frontend sends a follow-up message, it includes the `session_id` as a string (since JSON serialization converts numbers to strings), but the backend database expects an integer for the session lookup.

## Root Cause
In `backend/app/sio_events.py`, the session lookup code was:

```python
session_stmt = select(ChatSession).where(
    ChatSession.id == session_id,  # session_id might be string, but DB expects int
    ChatSession.user_id == user.id
)
```

## Fix Applied
1. **Type Conversion**: Added proper conversion of `session_id` from string to integer with error handling
2. **Better Logging**: Added detailed logging to help debug authentication and session lookup issues
3. **Error Handling**: Added specific error messages for invalid session ID format

## Changes Made

### 1. Enhanced Session ID Handling
```python
# Convert session_id to int if it's a string
try:
    session_id_int = int(session_id)
except (ValueError, TypeError):
    await sio.emit('error', {'error': 'Invalid session ID format'}, room=sid)
    return

# Use the integer version for database lookup
session_stmt = select(ChatSession).where(
    ChatSession.id == session_id_int,
    ChatSession.user_id == user.id
)
```

### 2. Improved Debugging
```python
# Added detailed logging for troubleshooting
logger.info(f"Socket.IO send_message: session_id={session_id} (type: {type(session_id)}), message_length={len(message) if message else 0}, use_consensus={use_consensus}, models={selected_models}")

logger.error(f"Chat session not found: session_id={session_id_int}, user_id={user.id}")

logger.error(f"Socket.IO authentication failed for token: {token[:20]}...")

logger.info(f"Socket.IO authenticated user: {user.id} ({user.username})")
```

## Expected Result
This fix should resolve the Socket.IO error that occurs when sending follow-up messages in an existing chat session. The error was likely happening because:

1. First message: Creates new session (no session_id conversion needed)
2. Follow-up message: Tries to look up existing session but fails due to string vs int mismatch

## Next Steps
1. Deploy these changes to Railway
2. Test the follow-up message scenario again
3. Monitor the backend logs for the new detailed debugging information

## Files Modified
- `backend/app/sio_events.py`: Enhanced session ID handling, added logging, improved error handling
